2024-02-19 06:25:56,793 ERROR frappe New Exception collected with id: 2024-02-19 06:25:56.697836-10.240.3.217-712
Site: erp.com
Form Dict: {}
2024-02-19 06:25:56,818 ERROR frappe Failed to run after request hook
Site: erp.com
Form Dict: {}
Traceback (most recent call last):
  File "/workspaces/dev/frappe-bench/env/lib/python3.10/site-packages/pymysql/connections.py", line 616, in connect
    sock = socket.create_connection(
  File "/home/codespace/.python/current/lib/python3.10/socket.py", line 845, in create_connection
    raise err
  File "/home/codespace/.python/current/lib/python3.10/socket.py", line 833, in create_connection
    sock.connect(sa)
ConnectionRefusedError: [Errno 111] Connection refused

During handling of the above exception, another exception occurred:

Traceback (most recent call last):
  File "/workspaces/dev/frappe-bench/apps/frappe/frappe/app.py", line 84, in application
    init_request(request)
  File "/workspaces/dev/frappe-bench/apps/frappe/frappe/app.py", line 175, in init_request
    frappe.local.http_request = frappe.auth.HTTPRequest()
  File "/workspaces/dev/frappe-bench/apps/frappe/frappe/auth.py", line 37, in __init__
    self.set_session()
  File "/workspaces/dev/frappe-bench/apps/frappe/frappe/auth.py", line 71, in set_session
    frappe.local.login_manager = LoginManager()
  File "/workspaces/dev/frappe-bench/apps/frappe/frappe/auth.py", line 117, in __init__
    self.make_session(resume=True)
  File "/workspaces/dev/frappe-bench/apps/frappe/frappe/auth.py", line 203, in make_session
    frappe.local.session_obj = Session(
  File "/workspaces/dev/frappe-bench/apps/frappe/frappe/sessions.py", line 222, in __init__
    self.resume()
  File "/workspaces/dev/frappe-bench/apps/frappe/frappe/sessions.py", line 298, in resume
    validate_ip_address(self.user)
  File "/workspaces/dev/frappe-bench/apps/frappe/frappe/auth.py", line 418, in validate_ip_address
    frappe.get_cached_value("User", user, user_fields, as_dict=True)
  File "/workspaces/dev/frappe-bench/apps/frappe/frappe/__init__.py", line 1152, in get_cached_value
    doc = get_cached_doc(doctype, name)
  File "/workspaces/dev/frappe-bench/apps/frappe/frappe/__init__.py", line 1095, in get_cached_doc
    doc = get_doc(*args, **kwargs)
  File "/workspaces/dev/frappe-bench/apps/frappe/frappe/__init__.py", line 1186, in get_doc
    doc = frappe.model.document.get_doc(*args, **kwargs)
  File "/workspaces/dev/frappe-bench/apps/frappe/frappe/model/document.py", line 73, in get_doc
    controller = get_controller(doctype)
  File "/workspaces/dev/frappe-bench/apps/frappe/frappe/model/base_document.py", line 89, in get_controller
    return _get_controller()
  File "/workspaces/dev/frappe-bench/apps/frappe/frappe/model/base_document.py", line 59, in _get_controller
    module_name, custom = frappe.db.get_value(
  File "/workspaces/dev/frappe-bench/apps/frappe/frappe/database/database.py", line 556, in get_value
    result = self.get_values(
  File "/workspaces/dev/frappe-bench/apps/frappe/frappe/database/database.py", line 653, in get_values
    out = self._get_values_from_table(
  File "/workspaces/dev/frappe-bench/apps/frappe/frappe/database/database.py", line 883, in _get_values_from_table
    return query.run(as_dict=as_dict, debug=debug, update=update, run=run, pluck=pluck)
  File "/workspaces/dev/frappe-bench/apps/frappe/frappe/query_builder/utils.py", line 87, in execute_query
    result = frappe.db.sql(query, params, *args, **kwargs)  # nosemgrep
  File "/workspaces/dev/frappe-bench/apps/frappe/frappe/database/database.py", line 220, in sql
    self.connect()
  File "/workspaces/dev/frappe-bench/apps/frappe/frappe/database/database.py", line 125, in connect
    self._conn: Union["MariadbConnection", "PostgresConnection"] = self.get_connection()
  File "/workspaces/dev/frappe-bench/apps/frappe/frappe/database/mariadb/database.py", line 99, in get_connection
    conn = self._get_connection()
  File "/workspaces/dev/frappe-bench/apps/frappe/frappe/database/mariadb/database.py", line 105, in _get_connection
    return self.create_connection()
  File "/workspaces/dev/frappe-bench/apps/frappe/frappe/database/mariadb/database.py", line 108, in create_connection
    return pymysql.connect(**self.get_connection_settings())
  File "/workspaces/dev/frappe-bench/env/lib/python3.10/site-packages/pymysql/connections.py", line 352, in __init__
    self.connect()
  File "/workspaces/dev/frappe-bench/env/lib/python3.10/site-packages/pymysql/connections.py", line 668, in connect
    raise exc
pymysql.err.OperationalError: (2003, "Can't connect to MySQL server on '127.0.0.1' ([Errno 111] Connection refused)")

During handling of the above exception, another exception occurred:

Traceback (most recent call last):
  File "/workspaces/dev/frappe-bench/apps/frappe/frappe/utils/caching.py", line 55, in wrapper
    return frappe.local.request_cache[func][args_key]
KeyError: 5740354900026072187

During handling of the above exception, another exception occurred:

Traceback (most recent call last):
  File "/workspaces/dev/frappe-bench/apps/frappe/frappe/utils/caching.py", line 55, in wrapper
    return frappe.local.request_cache[func][args_key]
KeyError: -5560454112137374563

During handling of the above exception, another exception occurred:

Traceback (most recent call last):
  File "/workspaces/dev/frappe-bench/env/lib/python3.10/site-packages/pymysql/connections.py", line 616, in connect
    sock = socket.create_connection(
  File "/home/codespace/.python/current/lib/python3.10/socket.py", line 845, in create_connection
    raise err
  File "/home/codespace/.python/current/lib/python3.10/socket.py", line 833, in create_connection
    sock.connect(sa)
ConnectionRefusedError: [Errno 111] Connection refused

During handling of the above exception, another exception occurred:

Traceback (most recent call last):
  File "/workspaces/dev/frappe-bench/apps/frappe/frappe/website/serve.py", line 17, in get_response
    endpoint, renderer_instance = path_resolver.resolve()
  File "/workspaces/dev/frappe-bench/apps/frappe/frappe/website/path_resolver.py", line 36, in resolve
    resolve_redirect(self.path, request.query_string)
  File "/workspaces/dev/frappe-bench/apps/frappe/frappe/website/path_resolver.py", line 107, in resolve_redirect
    redirects = frappe.get_hooks("website_redirects")
  File "/workspaces/dev/frappe-bench/apps/frappe/frappe/__init__.py", line 1498, in get_hooks
    hooks = _dict(cache().get_value("app_hooks", _load_app_hooks))
  File "/workspaces/dev/frappe-bench/apps/frappe/frappe/utils/redis_wrapper.py", line 81, in get_value
    val = generator()
  File "/workspaces/dev/frappe-bench/apps/frappe/frappe/utils/caching.py", line 57, in wrapper
    return_val = func(*args, **kwargs)
  File "/workspaces/dev/frappe-bench/apps/frappe/frappe/__init__.py", line 1463, in _load_app_hooks
    apps = [app_name] if app_name else get_installed_apps(_ensure_on_bench=True)
  File "/workspaces/dev/frappe-bench/apps/frappe/frappe/utils/caching.py", line 57, in wrapper
    return_val = func(*args, **kwargs)
  File "/workspaces/dev/frappe-bench/apps/frappe/frappe/__init__.py", line 1419, in get_installed_apps
    installed = json.loads(db.get_global("installed_apps") or "[]")
  File "/workspaces/dev/frappe-bench/apps/frappe/frappe/database/database.py", line 1023, in get_global
    return self.get_default(key, user)
  File "/workspaces/dev/frappe-bench/apps/frappe/frappe/database/database.py", line 1027, in get_default
    d = self.get_defaults(key, parent)
  File "/workspaces/dev/frappe-bench/apps/frappe/frappe/database/database.py", line 1043, in get_defaults
    defaults = frappe.defaults.get_defaults_for(parent)
  File "/workspaces/dev/frappe-bench/apps/frappe/frappe/defaults.py", line 238, in get_defaults_for
    frappe.qb.from_(table)
  File "/workspaces/dev/frappe-bench/apps/frappe/frappe/query_builder/utils.py", line 87, in execute_query
    result = frappe.db.sql(query, params, *args, **kwargs)  # nosemgrep
  File "/workspaces/dev/frappe-bench/apps/frappe/frappe/database/database.py", line 220, in sql
    self.connect()
  File "/workspaces/dev/frappe-bench/apps/frappe/frappe/database/database.py", line 125, in connect
    self._conn: Union["MariadbConnection", "PostgresConnection"] = self.get_connection()
  File "/workspaces/dev/frappe-bench/apps/frappe/frappe/database/mariadb/database.py", line 99, in get_connection
    conn = self._get_connection()
  File "/workspaces/dev/frappe-bench/apps/frappe/frappe/database/mariadb/database.py", line 105, in _get_connection
    return self.create_connection()
  File "/workspaces/dev/frappe-bench/apps/frappe/frappe/database/mariadb/database.py", line 108, in create_connection
    return pymysql.connect(**self.get_connection_settings())
  File "/workspaces/dev/frappe-bench/env/lib/python3.10/site-packages/pymysql/connections.py", line 352, in __init__
    self.connect()
  File "/workspaces/dev/frappe-bench/env/lib/python3.10/site-packages/pymysql/connections.py", line 668, in connect
    raise exc
pymysql.err.OperationalError: (2003, "Can't connect to MySQL server on '127.0.0.1' ([Errno 111] Connection refused)")

During handling of the above exception, another exception occurred:

Traceback (most recent call last):
  File "/workspaces/dev/frappe-bench/apps/frappe/frappe/utils/caching.py", line 55, in wrapper
    return frappe.local.request_cache[func][args_key]
KeyError: 3896150294578460377

During handling of the above exception, another exception occurred:

Traceback (most recent call last):
  File "/workspaces/dev/frappe-bench/env/lib/python3.10/site-packages/pymysql/connections.py", line 616, in connect
    sock = socket.create_connection(
  File "/home/codespace/.python/current/lib/python3.10/socket.py", line 845, in create_connection
    raise err
  File "/home/codespace/.python/current/lib/python3.10/socket.py", line 833, in create_connection
    sock.connect(sa)
ConnectionRefusedError: [Errno 111] Connection refused

During handling of the above exception, another exception occurred:

Traceback (most recent call last):
  File "/workspaces/dev/frappe-bench/apps/frappe/frappe/app.py", line 113, in application
    response = handle_exception(e)
  File "/workspaces/dev/frappe-bench/apps/frappe/frappe/app.py", line 367, in handle_exception
    response = get_response("message", http_status_code=http_status_code)
  File "/workspaces/dev/frappe-bench/apps/frappe/frappe/website/serve.py", line 26, in get_response
    response = ErrorPage(exception=e).render()
  File "/workspaces/dev/frappe-bench/apps/frappe/frappe/website/page_renderers/error_page.py", line 7, in __init__
    super().__init__(path=path, http_status_code=http_status_code)
  File "/workspaces/dev/frappe-bench/apps/frappe/frappe/website/page_renderers/template_page.py", line 45, in __init__
    self.set_template_path()
  File "/workspaces/dev/frappe-bench/apps/frappe/frappe/website/page_renderers/template_page.py", line 53, in set_template_path
    for app in frappe.get_installed_apps(frappe_last=True):
  File "/workspaces/dev/frappe-bench/apps/frappe/frappe/utils/caching.py", line 57, in wrapper
    return_val = func(*args, **kwargs)
  File "/workspaces/dev/frappe-bench/apps/frappe/frappe/__init__.py", line 1419, in get_installed_apps
    installed = json.loads(db.get_global("installed_apps") or "[]")
  File "/workspaces/dev/frappe-bench/apps/frappe/frappe/database/database.py", line 1023, in get_global
    return self.get_default(key, user)
  File "/workspaces/dev/frappe-bench/apps/frappe/frappe/database/database.py", line 1027, in get_default
    d = self.get_defaults(key, parent)
  File "/workspaces/dev/frappe-bench/apps/frappe/frappe/database/database.py", line 1043, in get_defaults
    defaults = frappe.defaults.get_defaults_for(parent)
  File "/workspaces/dev/frappe-bench/apps/frappe/frappe/defaults.py", line 238, in get_defaults_for
    frappe.qb.from_(table)
  File "/workspaces/dev/frappe-bench/apps/frappe/frappe/query_builder/utils.py", line 87, in execute_query
    result = frappe.db.sql(query, params, *args, **kwargs)  # nosemgrep
  File "/workspaces/dev/frappe-bench/apps/frappe/frappe/database/database.py", line 220, in sql
    self.connect()
  File "/workspaces/dev/frappe-bench/apps/frappe/frappe/database/database.py", line 125, in connect
    self._conn: Union["MariadbConnection", "PostgresConnection"] = self.get_connection()
  File "/workspaces/dev/frappe-bench/apps/frappe/frappe/database/mariadb/database.py", line 99, in get_connection
    conn = self._get_connection()
  File "/workspaces/dev/frappe-bench/apps/frappe/frappe/database/mariadb/database.py", line 105, in _get_connection
    return self.create_connection()
  File "/workspaces/dev/frappe-bench/apps/frappe/frappe/database/mariadb/database.py", line 108, in create_connection
    return pymysql.connect(**self.get_connection_settings())
  File "/workspaces/dev/frappe-bench/env/lib/python3.10/site-packages/pymysql/connections.py", line 352, in __init__
    self.connect()
  File "/workspaces/dev/frappe-bench/env/lib/python3.10/site-packages/pymysql/connections.py", line 668, in connect
    raise exc
pymysql.err.OperationalError: (2003, "Can't connect to MySQL server on '127.0.0.1' ([Errno 111] Connection refused)")

During handling of the above exception, another exception occurred:

Traceback (most recent call last):
  File "/workspaces/dev/frappe-bench/apps/frappe/frappe/utils/caching.py", line 55, in wrapper
    return frappe.local.request_cache[func][args_key]
KeyError: 5740354900026072187

During handling of the above exception, another exception occurred:

Traceback (most recent call last):
  File "/workspaces/dev/frappe-bench/apps/frappe/frappe/utils/caching.py", line 55, in wrapper
    return frappe.local.request_cache[func][args_key]
KeyError: -5560454112137374563

During handling of the above exception, another exception occurred:

Traceback (most recent call last):
  File "/workspaces/dev/frappe-bench/env/lib/python3.10/site-packages/pymysql/connections.py", line 616, in connect
    sock = socket.create_connection(
  File "/home/codespace/.python/current/lib/python3.10/socket.py", line 845, in create_connection
    raise err
  File "/home/codespace/.python/current/lib/python3.10/socket.py", line 833, in create_connection
    sock.connect(sa)
ConnectionRefusedError: [Errno 111] Connection refused

During handling of the above exception, another exception occurred:

Traceback (most recent call last):
  File "/workspaces/dev/frappe-bench/apps/frappe/frappe/app.py", line 127, in application
    run_after_request_hooks(request, response)
  File "/workspaces/dev/frappe-bench/apps/frappe/frappe/app.py", line 143, in run_after_request_hooks
    for after_request_task in frappe.get_hooks("after_request"):
  File "/workspaces/dev/frappe-bench/apps/frappe/frappe/__init__.py", line 1498, in get_hooks
    hooks = _dict(cache().get_value("app_hooks", _load_app_hooks))
  File "/workspaces/dev/frappe-bench/apps/frappe/frappe/utils/redis_wrapper.py", line 81, in get_value
    val = generator()
  File "/workspaces/dev/frappe-bench/apps/frappe/frappe/utils/caching.py", line 57, in wrapper
    return_val = func(*args, **kwargs)
  File "/workspaces/dev/frappe-bench/apps/frappe/frappe/__init__.py", line 1463, in _load_app_hooks
    apps = [app_name] if app_name else get_installed_apps(_ensure_on_bench=True)
  File "/workspaces/dev/frappe-bench/apps/frappe/frappe/utils/caching.py", line 57, in wrapper
    return_val = func(*args, **kwargs)
  File "/workspaces/dev/frappe-bench/apps/frappe/frappe/__init__.py", line 1419, in get_installed_apps
    installed = json.loads(db.get_global("installed_apps") or "[]")
  File "/workspaces/dev/frappe-bench/apps/frappe/frappe/database/database.py", line 1023, in get_global
    return self.get_default(key, user)
  File "/workspaces/dev/frappe-bench/apps/frappe/frappe/database/database.py", line 1027, in get_default
    d = self.get_defaults(key, parent)
  File "/workspaces/dev/frappe-bench/apps/frappe/frappe/database/database.py", line 1043, in get_defaults
    defaults = frappe.defaults.get_defaults_for(parent)
  File "/workspaces/dev/frappe-bench/apps/frappe/frappe/defaults.py", line 238, in get_defaults_for
    frappe.qb.from_(table)
  File "/workspaces/dev/frappe-bench/apps/frappe/frappe/query_builder/utils.py", line 87, in execute_query
    result = frappe.db.sql(query, params, *args, **kwargs)  # nosemgrep
  File "/workspaces/dev/frappe-bench/apps/frappe/frappe/database/database.py", line 220, in sql
    self.connect()
  File "/workspaces/dev/frappe-bench/apps/frappe/frappe/database/database.py", line 125, in connect
    self._conn: Union["MariadbConnection", "PostgresConnection"] = self.get_connection()
  File "/workspaces/dev/frappe-bench/apps/frappe/frappe/database/mariadb/database.py", line 99, in get_connection
    conn = self._get_connection()
  File "/workspaces/dev/frappe-bench/apps/frappe/frappe/database/mariadb/database.py", line 105, in _get_connection
    return self.create_connection()
  File "/workspaces/dev/frappe-bench/apps/frappe/frappe/database/mariadb/database.py", line 108, in create_connection
    return pymysql.connect(**self.get_connection_settings())
  File "/workspaces/dev/frappe-bench/env/lib/python3.10/site-packages/pymysql/connections.py", line 352, in __init__
    self.connect()
  File "/workspaces/dev/frappe-bench/env/lib/python3.10/site-packages/pymysql/connections.py", line 668, in connect
    raise exc
pymysql.err.OperationalError: (2003, "Can't connect to MySQL server on '127.0.0.1' ([Errno 111] Connection refused)")
2024-02-19 06:26:33,151 ERROR frappe New Exception collected with id: 2024-02-19 06:26:33.145503-10.240.3.217-532
Site: erp.com
Form Dict: {}
2024-02-19 06:26:33,155 ERROR frappe Failed to run after request hook
Site: erp.com
Form Dict: {}
Traceback (most recent call last):
  File "/workspaces/dev/frappe-bench/env/lib/python3.10/site-packages/pymysql/connections.py", line 616, in connect
    sock = socket.create_connection(
  File "/home/codespace/.python/current/lib/python3.10/socket.py", line 845, in create_connection
    raise err
  File "/home/codespace/.python/current/lib/python3.10/socket.py", line 833, in create_connection
    sock.connect(sa)
ConnectionRefusedError: [Errno 111] Connection refused

During handling of the above exception, another exception occurred:

Traceback (most recent call last):
  File "/workspaces/dev/frappe-bench/apps/frappe/frappe/app.py", line 84, in application
    init_request(request)
  File "/workspaces/dev/frappe-bench/apps/frappe/frappe/app.py", line 175, in init_request
    frappe.local.http_request = frappe.auth.HTTPRequest()
  File "/workspaces/dev/frappe-bench/apps/frappe/frappe/auth.py", line 37, in __init__
    self.set_session()
  File "/workspaces/dev/frappe-bench/apps/frappe/frappe/auth.py", line 71, in set_session
    frappe.local.login_manager = LoginManager()
  File "/workspaces/dev/frappe-bench/apps/frappe/frappe/auth.py", line 117, in __init__
    self.make_session(resume=True)
  File "/workspaces/dev/frappe-bench/apps/frappe/frappe/auth.py", line 203, in make_session
    frappe.local.session_obj = Session(
  File "/workspaces/dev/frappe-bench/apps/frappe/frappe/sessions.py", line 222, in __init__
    self.resume()
  File "/workspaces/dev/frappe-bench/apps/frappe/frappe/sessions.py", line 298, in resume
    validate_ip_address(self.user)
  File "/workspaces/dev/frappe-bench/apps/frappe/frappe/auth.py", line 418, in validate_ip_address
    frappe.get_cached_value("User", user, user_fields, as_dict=True)
  File "/workspaces/dev/frappe-bench/apps/frappe/frappe/__init__.py", line 1152, in get_cached_value
    doc = get_cached_doc(doctype, name)
  File "/workspaces/dev/frappe-bench/apps/frappe/frappe/__init__.py", line 1095, in get_cached_doc
    doc = get_doc(*args, **kwargs)
  File "/workspaces/dev/frappe-bench/apps/frappe/frappe/__init__.py", line 1186, in get_doc
    doc = frappe.model.document.get_doc(*args, **kwargs)
  File "/workspaces/dev/frappe-bench/apps/frappe/frappe/model/document.py", line 73, in get_doc
    controller = get_controller(doctype)
  File "/workspaces/dev/frappe-bench/apps/frappe/frappe/model/base_document.py", line 89, in get_controller
    return _get_controller()
  File "/workspaces/dev/frappe-bench/apps/frappe/frappe/model/base_document.py", line 59, in _get_controller
    module_name, custom = frappe.db.get_value(
  File "/workspaces/dev/frappe-bench/apps/frappe/frappe/database/database.py", line 556, in get_value
    result = self.get_values(
  File "/workspaces/dev/frappe-bench/apps/frappe/frappe/database/database.py", line 653, in get_values
    out = self._get_values_from_table(
  File "/workspaces/dev/frappe-bench/apps/frappe/frappe/database/database.py", line 883, in _get_values_from_table
    return query.run(as_dict=as_dict, debug=debug, update=update, run=run, pluck=pluck)
  File "/workspaces/dev/frappe-bench/apps/frappe/frappe/query_builder/utils.py", line 87, in execute_query
    result = frappe.db.sql(query, params, *args, **kwargs)  # nosemgrep
  File "/workspaces/dev/frappe-bench/apps/frappe/frappe/database/database.py", line 220, in sql
    self.connect()
  File "/workspaces/dev/frappe-bench/apps/frappe/frappe/database/database.py", line 125, in connect
    self._conn: Union["MariadbConnection", "PostgresConnection"] = self.get_connection()
  File "/workspaces/dev/frappe-bench/apps/frappe/frappe/database/mariadb/database.py", line 99, in get_connection
    conn = self._get_connection()
  File "/workspaces/dev/frappe-bench/apps/frappe/frappe/database/mariadb/database.py", line 105, in _get_connection
    return self.create_connection()
  File "/workspaces/dev/frappe-bench/apps/frappe/frappe/database/mariadb/database.py", line 108, in create_connection
    return pymysql.connect(**self.get_connection_settings())
  File "/workspaces/dev/frappe-bench/env/lib/python3.10/site-packages/pymysql/connections.py", line 352, in __init__
    self.connect()
  File "/workspaces/dev/frappe-bench/env/lib/python3.10/site-packages/pymysql/connections.py", line 668, in connect
    raise exc
pymysql.err.OperationalError: (2003, "Can't connect to MySQL server on '127.0.0.1' ([Errno 111] Connection refused)")

During handling of the above exception, another exception occurred:

Traceback (most recent call last):
  File "/workspaces/dev/frappe-bench/apps/frappe/frappe/utils/caching.py", line 55, in wrapper
    return frappe.local.request_cache[func][args_key]
KeyError: 5740354900026072187

During handling of the above exception, another exception occurred:

Traceback (most recent call last):
  File "/workspaces/dev/frappe-bench/apps/frappe/frappe/utils/caching.py", line 55, in wrapper
    return frappe.local.request_cache[func][args_key]
KeyError: -5560454112137374563

During handling of the above exception, another exception occurred:

Traceback (most recent call last):
  File "/workspaces/dev/frappe-bench/env/lib/python3.10/site-packages/pymysql/connections.py", line 616, in connect
    sock = socket.create_connection(
  File "/home/codespace/.python/current/lib/python3.10/socket.py", line 845, in create_connection
    raise err
  File "/home/codespace/.python/current/lib/python3.10/socket.py", line 833, in create_connection
    sock.connect(sa)
ConnectionRefusedError: [Errno 111] Connection refused

During handling of the above exception, another exception occurred:

Traceback (most recent call last):
  File "/workspaces/dev/frappe-bench/apps/frappe/frappe/website/serve.py", line 17, in get_response
    endpoint, renderer_instance = path_resolver.resolve()
  File "/workspaces/dev/frappe-bench/apps/frappe/frappe/website/path_resolver.py", line 36, in resolve
    resolve_redirect(self.path, request.query_string)
  File "/workspaces/dev/frappe-bench/apps/frappe/frappe/website/path_resolver.py", line 107, in resolve_redirect
    redirects = frappe.get_hooks("website_redirects")
  File "/workspaces/dev/frappe-bench/apps/frappe/frappe/__init__.py", line 1498, in get_hooks
    hooks = _dict(cache().get_value("app_hooks", _load_app_hooks))
  File "/workspaces/dev/frappe-bench/apps/frappe/frappe/utils/redis_wrapper.py", line 81, in get_value
    val = generator()
  File "/workspaces/dev/frappe-bench/apps/frappe/frappe/utils/caching.py", line 57, in wrapper
    return_val = func(*args, **kwargs)
  File "/workspaces/dev/frappe-bench/apps/frappe/frappe/__init__.py", line 1463, in _load_app_hooks
    apps = [app_name] if app_name else get_installed_apps(_ensure_on_bench=True)
  File "/workspaces/dev/frappe-bench/apps/frappe/frappe/utils/caching.py", line 57, in wrapper
    return_val = func(*args, **kwargs)
  File "/workspaces/dev/frappe-bench/apps/frappe/frappe/__init__.py", line 1419, in get_installed_apps
    installed = json.loads(db.get_global("installed_apps") or "[]")
  File "/workspaces/dev/frappe-bench/apps/frappe/frappe/database/database.py", line 1023, in get_global
    return self.get_default(key, user)
  File "/workspaces/dev/frappe-bench/apps/frappe/frappe/database/database.py", line 1027, in get_default
    d = self.get_defaults(key, parent)
  File "/workspaces/dev/frappe-bench/apps/frappe/frappe/database/database.py", line 1043, in get_defaults
    defaults = frappe.defaults.get_defaults_for(parent)
  File "/workspaces/dev/frappe-bench/apps/frappe/frappe/defaults.py", line 238, in get_defaults_for
    frappe.qb.from_(table)
  File "/workspaces/dev/frappe-bench/apps/frappe/frappe/query_builder/utils.py", line 87, in execute_query
    result = frappe.db.sql(query, params, *args, **kwargs)  # nosemgrep
  File "/workspaces/dev/frappe-bench/apps/frappe/frappe/database/database.py", line 220, in sql
    self.connect()
  File "/workspaces/dev/frappe-bench/apps/frappe/frappe/database/database.py", line 125, in connect
    self._conn: Union["MariadbConnection", "PostgresConnection"] = self.get_connection()
  File "/workspaces/dev/frappe-bench/apps/frappe/frappe/database/mariadb/database.py", line 99, in get_connection
    conn = self._get_connection()
  File "/workspaces/dev/frappe-bench/apps/frappe/frappe/database/mariadb/database.py", line 105, in _get_connection
    return self.create_connection()
  File "/workspaces/dev/frappe-bench/apps/frappe/frappe/database/mariadb/database.py", line 108, in create_connection
    return pymysql.connect(**self.get_connection_settings())
  File "/workspaces/dev/frappe-bench/env/lib/python3.10/site-packages/pymysql/connections.py", line 352, in __init__
    self.connect()
  File "/workspaces/dev/frappe-bench/env/lib/python3.10/site-packages/pymysql/connections.py", line 668, in connect
    raise exc
pymysql.err.OperationalError: (2003, "Can't connect to MySQL server on '127.0.0.1' ([Errno 111] Connection refused)")

During handling of the above exception, another exception occurred:

Traceback (most recent call last):
  File "/workspaces/dev/frappe-bench/apps/frappe/frappe/utils/caching.py", line 55, in wrapper
    return frappe.local.request_cache[func][args_key]
KeyError: 3896150294578460377

During handling of the above exception, another exception occurred:

Traceback (most recent call last):
  File "/workspaces/dev/frappe-bench/env/lib/python3.10/site-packages/pymysql/connections.py", line 616, in connect
    sock = socket.create_connection(
  File "/home/codespace/.python/current/lib/python3.10/socket.py", line 845, in create_connection
    raise err
  File "/home/codespace/.python/current/lib/python3.10/socket.py", line 833, in create_connection
    sock.connect(sa)
ConnectionRefusedError: [Errno 111] Connection refused

During handling of the above exception, another exception occurred:

Traceback (most recent call last):
  File "/workspaces/dev/frappe-bench/apps/frappe/frappe/app.py", line 113, in application
    response = handle_exception(e)
  File "/workspaces/dev/frappe-bench/apps/frappe/frappe/app.py", line 367, in handle_exception
    response = get_response("message", http_status_code=http_status_code)
  File "/workspaces/dev/frappe-bench/apps/frappe/frappe/website/serve.py", line 26, in get_response
    response = ErrorPage(exception=e).render()
  File "/workspaces/dev/frappe-bench/apps/frappe/frappe/website/page_renderers/error_page.py", line 7, in __init__
    super().__init__(path=path, http_status_code=http_status_code)
  File "/workspaces/dev/frappe-bench/apps/frappe/frappe/website/page_renderers/template_page.py", line 45, in __init__
    self.set_template_path()
  File "/workspaces/dev/frappe-bench/apps/frappe/frappe/website/page_renderers/template_page.py", line 53, in set_template_path
    for app in frappe.get_installed_apps(frappe_last=True):
  File "/workspaces/dev/frappe-bench/apps/frappe/frappe/utils/caching.py", line 57, in wrapper
    return_val = func(*args, **kwargs)
  File "/workspaces/dev/frappe-bench/apps/frappe/frappe/__init__.py", line 1419, in get_installed_apps
    installed = json.loads(db.get_global("installed_apps") or "[]")
  File "/workspaces/dev/frappe-bench/apps/frappe/frappe/database/database.py", line 1023, in get_global
    return self.get_default(key, user)
  File "/workspaces/dev/frappe-bench/apps/frappe/frappe/database/database.py", line 1027, in get_default
    d = self.get_defaults(key, parent)
  File "/workspaces/dev/frappe-bench/apps/frappe/frappe/database/database.py", line 1043, in get_defaults
    defaults = frappe.defaults.get_defaults_for(parent)
  File "/workspaces/dev/frappe-bench/apps/frappe/frappe/defaults.py", line 238, in get_defaults_for
    frappe.qb.from_(table)
  File "/workspaces/dev/frappe-bench/apps/frappe/frappe/query_builder/utils.py", line 87, in execute_query
    result = frappe.db.sql(query, params, *args, **kwargs)  # nosemgrep
  File "/workspaces/dev/frappe-bench/apps/frappe/frappe/database/database.py", line 220, in sql
    self.connect()
  File "/workspaces/dev/frappe-bench/apps/frappe/frappe/database/database.py", line 125, in connect
    self._conn: Union["MariadbConnection", "PostgresConnection"] = self.get_connection()
  File "/workspaces/dev/frappe-bench/apps/frappe/frappe/database/mariadb/database.py", line 99, in get_connection
    conn = self._get_connection()
  File "/workspaces/dev/frappe-bench/apps/frappe/frappe/database/mariadb/database.py", line 105, in _get_connection
    return self.create_connection()
  File "/workspaces/dev/frappe-bench/apps/frappe/frappe/database/mariadb/database.py", line 108, in create_connection
    return pymysql.connect(**self.get_connection_settings())
  File "/workspaces/dev/frappe-bench/env/lib/python3.10/site-packages/pymysql/connections.py", line 352, in __init__
    self.connect()
  File "/workspaces/dev/frappe-bench/env/lib/python3.10/site-packages/pymysql/connections.py", line 668, in connect
    raise exc
pymysql.err.OperationalError: (2003, "Can't connect to MySQL server on '127.0.0.1' ([Errno 111] Connection refused)")

During handling of the above exception, another exception occurred:

Traceback (most recent call last):
  File "/workspaces/dev/frappe-bench/apps/frappe/frappe/utils/caching.py", line 55, in wrapper
    return frappe.local.request_cache[func][args_key]
KeyError: 5740354900026072187

During handling of the above exception, another exception occurred:

Traceback (most recent call last):
  File "/workspaces/dev/frappe-bench/apps/frappe/frappe/utils/caching.py", line 55, in wrapper
    return frappe.local.request_cache[func][args_key]
KeyError: -5560454112137374563

During handling of the above exception, another exception occurred:

Traceback (most recent call last):
  File "/workspaces/dev/frappe-bench/env/lib/python3.10/site-packages/pymysql/connections.py", line 616, in connect
    sock = socket.create_connection(
  File "/home/codespace/.python/current/lib/python3.10/socket.py", line 845, in create_connection
    raise err
  File "/home/codespace/.python/current/lib/python3.10/socket.py", line 833, in create_connection
    sock.connect(sa)
ConnectionRefusedError: [Errno 111] Connection refused

During handling of the above exception, another exception occurred:

Traceback (most recent call last):
  File "/workspaces/dev/frappe-bench/apps/frappe/frappe/app.py", line 127, in application
    run_after_request_hooks(request, response)
  File "/workspaces/dev/frappe-bench/apps/frappe/frappe/app.py", line 143, in run_after_request_hooks
    for after_request_task in frappe.get_hooks("after_request"):
  File "/workspaces/dev/frappe-bench/apps/frappe/frappe/__init__.py", line 1498, in get_hooks
    hooks = _dict(cache().get_value("app_hooks", _load_app_hooks))
  File "/workspaces/dev/frappe-bench/apps/frappe/frappe/utils/redis_wrapper.py", line 81, in get_value
    val = generator()
  File "/workspaces/dev/frappe-bench/apps/frappe/frappe/utils/caching.py", line 57, in wrapper
    return_val = func(*args, **kwargs)
  File "/workspaces/dev/frappe-bench/apps/frappe/frappe/__init__.py", line 1463, in _load_app_hooks
    apps = [app_name] if app_name else get_installed_apps(_ensure_on_bench=True)
  File "/workspaces/dev/frappe-bench/apps/frappe/frappe/utils/caching.py", line 57, in wrapper
    return_val = func(*args, **kwargs)
  File "/workspaces/dev/frappe-bench/apps/frappe/frappe/__init__.py", line 1419, in get_installed_apps
    installed = json.loads(db.get_global("installed_apps") or "[]")
  File "/workspaces/dev/frappe-bench/apps/frappe/frappe/database/database.py", line 1023, in get_global
    return self.get_default(key, user)
  File "/workspaces/dev/frappe-bench/apps/frappe/frappe/database/database.py", line 1027, in get_default
    d = self.get_defaults(key, parent)
  File "/workspaces/dev/frappe-bench/apps/frappe/frappe/database/database.py", line 1043, in get_defaults
    defaults = frappe.defaults.get_defaults_for(parent)
  File "/workspaces/dev/frappe-bench/apps/frappe/frappe/defaults.py", line 238, in get_defaults_for
    frappe.qb.from_(table)
  File "/workspaces/dev/frappe-bench/apps/frappe/frappe/query_builder/utils.py", line 87, in execute_query
    result = frappe.db.sql(query, params, *args, **kwargs)  # nosemgrep
  File "/workspaces/dev/frappe-bench/apps/frappe/frappe/database/database.py", line 220, in sql
    self.connect()
  File "/workspaces/dev/frappe-bench/apps/frappe/frappe/database/database.py", line 125, in connect
    self._conn: Union["MariadbConnection", "PostgresConnection"] = self.get_connection()
  File "/workspaces/dev/frappe-bench/apps/frappe/frappe/database/mariadb/database.py", line 99, in get_connection
    conn = self._get_connection()
  File "/workspaces/dev/frappe-bench/apps/frappe/frappe/database/mariadb/database.py", line 105, in _get_connection
    return self.create_connection()
  File "/workspaces/dev/frappe-bench/apps/frappe/frappe/database/mariadb/database.py", line 108, in create_connection
    return pymysql.connect(**self.get_connection_settings())
  File "/workspaces/dev/frappe-bench/env/lib/python3.10/site-packages/pymysql/connections.py", line 352, in __init__
    self.connect()
  File "/workspaces/dev/frappe-bench/env/lib/python3.10/site-packages/pymysql/connections.py", line 668, in connect
    raise exc
pymysql.err.OperationalError: (2003, "Can't connect to MySQL server on '127.0.0.1' ([Errno 111] Connection refused)")
2024-02-19 09:02:12,293 ERROR frappe New Exception collected with id: 2024-02-19 09:02:12.146142-127.0.0.1-f23
Site: erp.com
Form Dict: {}
2024-02-19 09:02:12,430 ERROR frappe Failed to run after request hook
Site: erp.com
Form Dict: {}
Traceback (most recent call last):
  File "/workspaces/dev/frappe-bench/env/lib/python3.10/site-packages/pymysql/connections.py", line 616, in connect
    sock = socket.create_connection(
  File "/home/codespace/.python/current/lib/python3.10/socket.py", line 845, in create_connection
    raise err
  File "/home/codespace/.python/current/lib/python3.10/socket.py", line 833, in create_connection
    sock.connect(sa)
ConnectionRefusedError: [Errno 111] Connection refused

During handling of the above exception, another exception occurred:

Traceback (most recent call last):
  File "/workspaces/dev/frappe-bench/apps/frappe/frappe/app.py", line 84, in application
    init_request(request)
  File "/workspaces/dev/frappe-bench/apps/frappe/frappe/app.py", line 175, in init_request
    frappe.local.http_request = frappe.auth.HTTPRequest()
  File "/workspaces/dev/frappe-bench/apps/frappe/frappe/auth.py", line 37, in __init__
    self.set_session()
  File "/workspaces/dev/frappe-bench/apps/frappe/frappe/auth.py", line 71, in set_session
    frappe.local.login_manager = LoginManager()
  File "/workspaces/dev/frappe-bench/apps/frappe/frappe/auth.py", line 117, in __init__
    self.make_session(resume=True)
  File "/workspaces/dev/frappe-bench/apps/frappe/frappe/auth.py", line 203, in make_session
    frappe.local.session_obj = Session(
  File "/workspaces/dev/frappe-bench/apps/frappe/frappe/sessions.py", line 222, in __init__
    self.resume()
  File "/workspaces/dev/frappe-bench/apps/frappe/frappe/sessions.py", line 298, in resume
    validate_ip_address(self.user)
  File "/workspaces/dev/frappe-bench/apps/frappe/frappe/auth.py", line 418, in validate_ip_address
    frappe.get_cached_value("User", user, user_fields, as_dict=True)
  File "/workspaces/dev/frappe-bench/apps/frappe/frappe/__init__.py", line 1152, in get_cached_value
    doc = get_cached_doc(doctype, name)
  File "/workspaces/dev/frappe-bench/apps/frappe/frappe/__init__.py", line 1095, in get_cached_doc
    doc = get_doc(*args, **kwargs)
  File "/workspaces/dev/frappe-bench/apps/frappe/frappe/__init__.py", line 1186, in get_doc
    doc = frappe.model.document.get_doc(*args, **kwargs)
  File "/workspaces/dev/frappe-bench/apps/frappe/frappe/model/document.py", line 73, in get_doc
    controller = get_controller(doctype)
  File "/workspaces/dev/frappe-bench/apps/frappe/frappe/model/base_document.py", line 89, in get_controller
    return _get_controller()
  File "/workspaces/dev/frappe-bench/apps/frappe/frappe/model/base_document.py", line 59, in _get_controller
    module_name, custom = frappe.db.get_value(
  File "/workspaces/dev/frappe-bench/apps/frappe/frappe/database/database.py", line 556, in get_value
    result = self.get_values(
  File "/workspaces/dev/frappe-bench/apps/frappe/frappe/database/database.py", line 653, in get_values
    out = self._get_values_from_table(
  File "/workspaces/dev/frappe-bench/apps/frappe/frappe/database/database.py", line 883, in _get_values_from_table
    return query.run(as_dict=as_dict, debug=debug, update=update, run=run, pluck=pluck)
  File "/workspaces/dev/frappe-bench/apps/frappe/frappe/query_builder/utils.py", line 87, in execute_query
    result = frappe.db.sql(query, params, *args, **kwargs)  # nosemgrep
  File "/workspaces/dev/frappe-bench/apps/frappe/frappe/database/database.py", line 220, in sql
    self.connect()
  File "/workspaces/dev/frappe-bench/apps/frappe/frappe/database/database.py", line 125, in connect
    self._conn: Union["MariadbConnection", "PostgresConnection"] = self.get_connection()
  File "/workspaces/dev/frappe-bench/apps/frappe/frappe/database/mariadb/database.py", line 99, in get_connection
    conn = self._get_connection()
  File "/workspaces/dev/frappe-bench/apps/frappe/frappe/database/mariadb/database.py", line 105, in _get_connection
    return self.create_connection()
  File "/workspaces/dev/frappe-bench/apps/frappe/frappe/database/mariadb/database.py", line 108, in create_connection
    return pymysql.connect(**self.get_connection_settings())
  File "/workspaces/dev/frappe-bench/env/lib/python3.10/site-packages/pymysql/connections.py", line 352, in __init__
    self.connect()
  File "/workspaces/dev/frappe-bench/env/lib/python3.10/site-packages/pymysql/connections.py", line 668, in connect
    raise exc
pymysql.err.OperationalError: (2003, "Can't connect to MySQL server on '127.0.0.1' ([Errno 111] Connection refused)")

During handling of the above exception, another exception occurred:

Traceback (most recent call last):
  File "/workspaces/dev/frappe-bench/apps/frappe/frappe/utils/caching.py", line 55, in wrapper
    return frappe.local.request_cache[func][args_key]
KeyError: 5740354900026072187

During handling of the above exception, another exception occurred:

Traceback (most recent call last):
  File "/workspaces/dev/frappe-bench/apps/frappe/frappe/utils/caching.py", line 55, in wrapper
    return frappe.local.request_cache[func][args_key]
KeyError: 3887273024699398329

During handling of the above exception, another exception occurred:

Traceback (most recent call last):
  File "/workspaces/dev/frappe-bench/env/lib/python3.10/site-packages/pymysql/connections.py", line 616, in connect
    sock = socket.create_connection(
  File "/home/codespace/.python/current/lib/python3.10/socket.py", line 845, in create_connection
    raise err
  File "/home/codespace/.python/current/lib/python3.10/socket.py", line 833, in create_connection
    sock.connect(sa)
ConnectionRefusedError: [Errno 111] Connection refused

During handling of the above exception, another exception occurred:

Traceback (most recent call last):
  File "/workspaces/dev/frappe-bench/apps/frappe/frappe/website/serve.py", line 17, in get_response
    endpoint, renderer_instance = path_resolver.resolve()
  File "/workspaces/dev/frappe-bench/apps/frappe/frappe/website/path_resolver.py", line 36, in resolve
    resolve_redirect(self.path, request.query_string)
  File "/workspaces/dev/frappe-bench/apps/frappe/frappe/website/path_resolver.py", line 107, in resolve_redirect
    redirects = frappe.get_hooks("website_redirects")
  File "/workspaces/dev/frappe-bench/apps/frappe/frappe/__init__.py", line 1498, in get_hooks
    hooks = _dict(cache().get_value("app_hooks", _load_app_hooks))
  File "/workspaces/dev/frappe-bench/apps/frappe/frappe/utils/redis_wrapper.py", line 81, in get_value
    val = generator()
  File "/workspaces/dev/frappe-bench/apps/frappe/frappe/utils/caching.py", line 57, in wrapper
    return_val = func(*args, **kwargs)
  File "/workspaces/dev/frappe-bench/apps/frappe/frappe/__init__.py", line 1463, in _load_app_hooks
    apps = [app_name] if app_name else get_installed_apps(_ensure_on_bench=True)
  File "/workspaces/dev/frappe-bench/apps/frappe/frappe/utils/caching.py", line 57, in wrapper
    return_val = func(*args, **kwargs)
  File "/workspaces/dev/frappe-bench/apps/frappe/frappe/__init__.py", line 1419, in get_installed_apps
    installed = json.loads(db.get_global("installed_apps") or "[]")
  File "/workspaces/dev/frappe-bench/apps/frappe/frappe/database/database.py", line 1023, in get_global
    return self.get_default(key, user)
  File "/workspaces/dev/frappe-bench/apps/frappe/frappe/database/database.py", line 1027, in get_default
    d = self.get_defaults(key, parent)
  File "/workspaces/dev/frappe-bench/apps/frappe/frappe/database/database.py", line 1043, in get_defaults
    defaults = frappe.defaults.get_defaults_for(parent)
  File "/workspaces/dev/frappe-bench/apps/frappe/frappe/defaults.py", line 238, in get_defaults_for
    frappe.qb.from_(table)
  File "/workspaces/dev/frappe-bench/apps/frappe/frappe/query_builder/utils.py", line 87, in execute_query
    result = frappe.db.sql(query, params, *args, **kwargs)  # nosemgrep
  File "/workspaces/dev/frappe-bench/apps/frappe/frappe/database/database.py", line 220, in sql
    self.connect()
  File "/workspaces/dev/frappe-bench/apps/frappe/frappe/database/database.py", line 125, in connect
    self._conn: Union["MariadbConnection", "PostgresConnection"] = self.get_connection()
  File "/workspaces/dev/frappe-bench/apps/frappe/frappe/database/mariadb/database.py", line 99, in get_connection
    conn = self._get_connection()
  File "/workspaces/dev/frappe-bench/apps/frappe/frappe/database/mariadb/database.py", line 105, in _get_connection
    return self.create_connection()
  File "/workspaces/dev/frappe-bench/apps/frappe/frappe/database/mariadb/database.py", line 108, in create_connection
    return pymysql.connect(**self.get_connection_settings())
  File "/workspaces/dev/frappe-bench/env/lib/python3.10/site-packages/pymysql/connections.py", line 352, in __init__
    self.connect()
  File "/workspaces/dev/frappe-bench/env/lib/python3.10/site-packages/pymysql/connections.py", line 668, in connect
    raise exc
pymysql.err.OperationalError: (2003, "Can't connect to MySQL server on '127.0.0.1' ([Errno 111] Connection refused)")

During handling of the above exception, another exception occurred:

Traceback (most recent call last):
  File "/workspaces/dev/frappe-bench/apps/frappe/frappe/utils/caching.py", line 55, in wrapper
    return frappe.local.request_cache[func][args_key]
KeyError: 4350084734142961474

During handling of the above exception, another exception occurred:

Traceback (most recent call last):
  File "/workspaces/dev/frappe-bench/env/lib/python3.10/site-packages/pymysql/connections.py", line 616, in connect
    sock = socket.create_connection(
  File "/home/codespace/.python/current/lib/python3.10/socket.py", line 845, in create_connection
    raise err
  File "/home/codespace/.python/current/lib/python3.10/socket.py", line 833, in create_connection
    sock.connect(sa)
ConnectionRefusedError: [Errno 111] Connection refused

During handling of the above exception, another exception occurred:

Traceback (most recent call last):
  File "/workspaces/dev/frappe-bench/apps/frappe/frappe/app.py", line 113, in application
    response = handle_exception(e)
  File "/workspaces/dev/frappe-bench/apps/frappe/frappe/app.py", line 367, in handle_exception
    response = get_response("message", http_status_code=http_status_code)
  File "/workspaces/dev/frappe-bench/apps/frappe/frappe/website/serve.py", line 26, in get_response
    response = ErrorPage(exception=e).render()
  File "/workspaces/dev/frappe-bench/apps/frappe/frappe/website/page_renderers/error_page.py", line 7, in __init__
    super().__init__(path=path, http_status_code=http_status_code)
  File "/workspaces/dev/frappe-bench/apps/frappe/frappe/website/page_renderers/template_page.py", line 45, in __init__
    self.set_template_path()
  File "/workspaces/dev/frappe-bench/apps/frappe/frappe/website/page_renderers/template_page.py", line 53, in set_template_path
    for app in frappe.get_installed_apps(frappe_last=True):
  File "/workspaces/dev/frappe-bench/apps/frappe/frappe/utils/caching.py", line 57, in wrapper
    return_val = func(*args, **kwargs)
  File "/workspaces/dev/frappe-bench/apps/frappe/frappe/__init__.py", line 1419, in get_installed_apps
    installed = json.loads(db.get_global("installed_apps") or "[]")
  File "/workspaces/dev/frappe-bench/apps/frappe/frappe/database/database.py", line 1023, in get_global
    return self.get_default(key, user)
  File "/workspaces/dev/frappe-bench/apps/frappe/frappe/database/database.py", line 1027, in get_default
    d = self.get_defaults(key, parent)
  File "/workspaces/dev/frappe-bench/apps/frappe/frappe/database/database.py", line 1043, in get_defaults
    defaults = frappe.defaults.get_defaults_for(parent)
  File "/workspaces/dev/frappe-bench/apps/frappe/frappe/defaults.py", line 238, in get_defaults_for
    frappe.qb.from_(table)
  File "/workspaces/dev/frappe-bench/apps/frappe/frappe/query_builder/utils.py", line 87, in execute_query
    result = frappe.db.sql(query, params, *args, **kwargs)  # nosemgrep
  File "/workspaces/dev/frappe-bench/apps/frappe/frappe/database/database.py", line 220, in sql
    self.connect()
  File "/workspaces/dev/frappe-bench/apps/frappe/frappe/database/database.py", line 125, in connect
    self._conn: Union["MariadbConnection", "PostgresConnection"] = self.get_connection()
  File "/workspaces/dev/frappe-bench/apps/frappe/frappe/database/mariadb/database.py", line 99, in get_connection
    conn = self._get_connection()
  File "/workspaces/dev/frappe-bench/apps/frappe/frappe/database/mariadb/database.py", line 105, in _get_connection
    return self.create_connection()
  File "/workspaces/dev/frappe-bench/apps/frappe/frappe/database/mariadb/database.py", line 108, in create_connection
    return pymysql.connect(**self.get_connection_settings())
  File "/workspaces/dev/frappe-bench/env/lib/python3.10/site-packages/pymysql/connections.py", line 352, in __init__
    self.connect()
  File "/workspaces/dev/frappe-bench/env/lib/python3.10/site-packages/pymysql/connections.py", line 668, in connect
    raise exc
pymysql.err.OperationalError: (2003, "Can't connect to MySQL server on '127.0.0.1' ([Errno 111] Connection refused)")

During handling of the above exception, another exception occurred:

Traceback (most recent call last):
  File "/workspaces/dev/frappe-bench/apps/frappe/frappe/utils/caching.py", line 55, in wrapper
    return frappe.local.request_cache[func][args_key]
KeyError: 5740354900026072187

During handling of the above exception, another exception occurred:

Traceback (most recent call last):
  File "/workspaces/dev/frappe-bench/apps/frappe/frappe/utils/caching.py", line 55, in wrapper
    return frappe.local.request_cache[func][args_key]
KeyError: 3887273024699398329

During handling of the above exception, another exception occurred:

Traceback (most recent call last):
  File "/workspaces/dev/frappe-bench/env/lib/python3.10/site-packages/pymysql/connections.py", line 616, in connect
    sock = socket.create_connection(
  File "/home/codespace/.python/current/lib/python3.10/socket.py", line 845, in create_connection
    raise err
  File "/home/codespace/.python/current/lib/python3.10/socket.py", line 833, in create_connection
    sock.connect(sa)
ConnectionRefusedError: [Errno 111] Connection refused

During handling of the above exception, another exception occurred:

Traceback (most recent call last):
  File "/workspaces/dev/frappe-bench/apps/frappe/frappe/app.py", line 127, in application
    run_after_request_hooks(request, response)
  File "/workspaces/dev/frappe-bench/apps/frappe/frappe/app.py", line 143, in run_after_request_hooks
    for after_request_task in frappe.get_hooks("after_request"):
  File "/workspaces/dev/frappe-bench/apps/frappe/frappe/__init__.py", line 1498, in get_hooks
    hooks = _dict(cache().get_value("app_hooks", _load_app_hooks))
  File "/workspaces/dev/frappe-bench/apps/frappe/frappe/utils/redis_wrapper.py", line 81, in get_value
    val = generator()
  File "/workspaces/dev/frappe-bench/apps/frappe/frappe/utils/caching.py", line 57, in wrapper
    return_val = func(*args, **kwargs)
  File "/workspaces/dev/frappe-bench/apps/frappe/frappe/__init__.py", line 1463, in _load_app_hooks
    apps = [app_name] if app_name else get_installed_apps(_ensure_on_bench=True)
  File "/workspaces/dev/frappe-bench/apps/frappe/frappe/utils/caching.py", line 57, in wrapper
    return_val = func(*args, **kwargs)
  File "/workspaces/dev/frappe-bench/apps/frappe/frappe/__init__.py", line 1419, in get_installed_apps
    installed = json.loads(db.get_global("installed_apps") or "[]")
  File "/workspaces/dev/frappe-bench/apps/frappe/frappe/database/database.py", line 1023, in get_global
    return self.get_default(key, user)
  File "/workspaces/dev/frappe-bench/apps/frappe/frappe/database/database.py", line 1027, in get_default
    d = self.get_defaults(key, parent)
  File "/workspaces/dev/frappe-bench/apps/frappe/frappe/database/database.py", line 1043, in get_defaults
    defaults = frappe.defaults.get_defaults_for(parent)
  File "/workspaces/dev/frappe-bench/apps/frappe/frappe/defaults.py", line 238, in get_defaults_for
    frappe.qb.from_(table)
  File "/workspaces/dev/frappe-bench/apps/frappe/frappe/query_builder/utils.py", line 87, in execute_query
    result = frappe.db.sql(query, params, *args, **kwargs)  # nosemgrep
  File "/workspaces/dev/frappe-bench/apps/frappe/frappe/database/database.py", line 220, in sql
    self.connect()
  File "/workspaces/dev/frappe-bench/apps/frappe/frappe/database/database.py", line 125, in connect
    self._conn: Union["MariadbConnection", "PostgresConnection"] = self.get_connection()
  File "/workspaces/dev/frappe-bench/apps/frappe/frappe/database/mariadb/database.py", line 99, in get_connection
    conn = self._get_connection()
  File "/workspaces/dev/frappe-bench/apps/frappe/frappe/database/mariadb/database.py", line 105, in _get_connection
    return self.create_connection()
  File "/workspaces/dev/frappe-bench/apps/frappe/frappe/database/mariadb/database.py", line 108, in create_connection
    return pymysql.connect(**self.get_connection_settings())
  File "/workspaces/dev/frappe-bench/env/lib/python3.10/site-packages/pymysql/connections.py", line 352, in __init__
    self.connect()
  File "/workspaces/dev/frappe-bench/env/lib/python3.10/site-packages/pymysql/connections.py", line 668, in connect
    raise exc
pymysql.err.OperationalError: (2003, "Can't connect to MySQL server on '127.0.0.1' ([Errno 111] Connection refused)")
2024-02-19 09:03:50,992 ERROR frappe New Exception collected with id: 2024-02-19 09:03:50.633538-127.0.0.1-e4a
Site: erp.com
Form Dict: {}
2024-02-19 09:03:50,999 ERROR frappe Failed to run after request hook
Site: erp.com
Form Dict: {}
Traceback (most recent call last):
  File "/workspaces/dev/frappe-bench/env/lib/python3.10/site-packages/pymysql/connections.py", line 616, in connect
    sock = socket.create_connection(
  File "/home/codespace/.python/current/lib/python3.10/socket.py", line 845, in create_connection
    raise err
  File "/home/codespace/.python/current/lib/python3.10/socket.py", line 833, in create_connection
    sock.connect(sa)
ConnectionRefusedError: [Errno 111] Connection refused

During handling of the above exception, another exception occurred:

Traceback (most recent call last):
  File "/workspaces/dev/frappe-bench/apps/frappe/frappe/app.py", line 84, in application
    init_request(request)
  File "/workspaces/dev/frappe-bench/apps/frappe/frappe/app.py", line 175, in init_request
    frappe.local.http_request = frappe.auth.HTTPRequest()
  File "/workspaces/dev/frappe-bench/apps/frappe/frappe/auth.py", line 37, in __init__
    self.set_session()
  File "/workspaces/dev/frappe-bench/apps/frappe/frappe/auth.py", line 71, in set_session
    frappe.local.login_manager = LoginManager()
  File "/workspaces/dev/frappe-bench/apps/frappe/frappe/auth.py", line 117, in __init__
    self.make_session(resume=True)
  File "/workspaces/dev/frappe-bench/apps/frappe/frappe/auth.py", line 203, in make_session
    frappe.local.session_obj = Session(
  File "/workspaces/dev/frappe-bench/apps/frappe/frappe/sessions.py", line 222, in __init__
    self.resume()
  File "/workspaces/dev/frappe-bench/apps/frappe/frappe/sessions.py", line 298, in resume
    validate_ip_address(self.user)
  File "/workspaces/dev/frappe-bench/apps/frappe/frappe/auth.py", line 418, in validate_ip_address
    frappe.get_cached_value("User", user, user_fields, as_dict=True)
  File "/workspaces/dev/frappe-bench/apps/frappe/frappe/__init__.py", line 1152, in get_cached_value
    doc = get_cached_doc(doctype, name)
  File "/workspaces/dev/frappe-bench/apps/frappe/frappe/__init__.py", line 1095, in get_cached_doc
    doc = get_doc(*args, **kwargs)
  File "/workspaces/dev/frappe-bench/apps/frappe/frappe/__init__.py", line 1186, in get_doc
    doc = frappe.model.document.get_doc(*args, **kwargs)
  File "/workspaces/dev/frappe-bench/apps/frappe/frappe/model/document.py", line 73, in get_doc
    controller = get_controller(doctype)
  File "/workspaces/dev/frappe-bench/apps/frappe/frappe/model/base_document.py", line 89, in get_controller
    return _get_controller()
  File "/workspaces/dev/frappe-bench/apps/frappe/frappe/model/base_document.py", line 59, in _get_controller
    module_name, custom = frappe.db.get_value(
  File "/workspaces/dev/frappe-bench/apps/frappe/frappe/database/database.py", line 556, in get_value
    result = self.get_values(
  File "/workspaces/dev/frappe-bench/apps/frappe/frappe/database/database.py", line 653, in get_values
    out = self._get_values_from_table(
  File "/workspaces/dev/frappe-bench/apps/frappe/frappe/database/database.py", line 883, in _get_values_from_table
    return query.run(as_dict=as_dict, debug=debug, update=update, run=run, pluck=pluck)
  File "/workspaces/dev/frappe-bench/apps/frappe/frappe/query_builder/utils.py", line 87, in execute_query
    result = frappe.db.sql(query, params, *args, **kwargs)  # nosemgrep
  File "/workspaces/dev/frappe-bench/apps/frappe/frappe/database/database.py", line 220, in sql
    self.connect()
  File "/workspaces/dev/frappe-bench/apps/frappe/frappe/database/database.py", line 125, in connect
    self._conn: Union["MariadbConnection", "PostgresConnection"] = self.get_connection()
  File "/workspaces/dev/frappe-bench/apps/frappe/frappe/database/mariadb/database.py", line 99, in get_connection
    conn = self._get_connection()
  File "/workspaces/dev/frappe-bench/apps/frappe/frappe/database/mariadb/database.py", line 105, in _get_connection
    return self.create_connection()
  File "/workspaces/dev/frappe-bench/apps/frappe/frappe/database/mariadb/database.py", line 108, in create_connection
    return pymysql.connect(**self.get_connection_settings())
  File "/workspaces/dev/frappe-bench/env/lib/python3.10/site-packages/pymysql/connections.py", line 352, in __init__
    self.connect()
  File "/workspaces/dev/frappe-bench/env/lib/python3.10/site-packages/pymysql/connections.py", line 668, in connect
    raise exc
pymysql.err.OperationalError: (2003, "Can't connect to MySQL server on '127.0.0.1' ([Errno 111] Connection refused)")

During handling of the above exception, another exception occurred:

Traceback (most recent call last):
  File "/workspaces/dev/frappe-bench/apps/frappe/frappe/utils/caching.py", line 55, in wrapper
    return frappe.local.request_cache[func][args_key]
KeyError: 5740354900026072187

During handling of the above exception, another exception occurred:

Traceback (most recent call last):
  File "/workspaces/dev/frappe-bench/apps/frappe/frappe/utils/caching.py", line 55, in wrapper
    return frappe.local.request_cache[func][args_key]
KeyError: 1255897768722113620

During handling of the above exception, another exception occurred:

Traceback (most recent call last):
  File "/workspaces/dev/frappe-bench/env/lib/python3.10/site-packages/pymysql/connections.py", line 616, in connect
    sock = socket.create_connection(
  File "/home/codespace/.python/current/lib/python3.10/socket.py", line 845, in create_connection
    raise err
  File "/home/codespace/.python/current/lib/python3.10/socket.py", line 833, in create_connection
    sock.connect(sa)
ConnectionRefusedError: [Errno 111] Connection refused

During handling of the above exception, another exception occurred:

Traceback (most recent call last):
  File "/workspaces/dev/frappe-bench/apps/frappe/frappe/website/serve.py", line 17, in get_response
    endpoint, renderer_instance = path_resolver.resolve()
  File "/workspaces/dev/frappe-bench/apps/frappe/frappe/website/path_resolver.py", line 36, in resolve
    resolve_redirect(self.path, request.query_string)
  File "/workspaces/dev/frappe-bench/apps/frappe/frappe/website/path_resolver.py", line 107, in resolve_redirect
    redirects = frappe.get_hooks("website_redirects")
  File "/workspaces/dev/frappe-bench/apps/frappe/frappe/__init__.py", line 1498, in get_hooks
    hooks = _dict(cache().get_value("app_hooks", _load_app_hooks))
  File "/workspaces/dev/frappe-bench/apps/frappe/frappe/utils/redis_wrapper.py", line 81, in get_value
    val = generator()
  File "/workspaces/dev/frappe-bench/apps/frappe/frappe/utils/caching.py", line 57, in wrapper
    return_val = func(*args, **kwargs)
  File "/workspaces/dev/frappe-bench/apps/frappe/frappe/__init__.py", line 1463, in _load_app_hooks
    apps = [app_name] if app_name else get_installed_apps(_ensure_on_bench=True)
  File "/workspaces/dev/frappe-bench/apps/frappe/frappe/utils/caching.py", line 57, in wrapper
    return_val = func(*args, **kwargs)
  File "/workspaces/dev/frappe-bench/apps/frappe/frappe/__init__.py", line 1419, in get_installed_apps
    installed = json.loads(db.get_global("installed_apps") or "[]")
  File "/workspaces/dev/frappe-bench/apps/frappe/frappe/database/database.py", line 1023, in get_global
    return self.get_default(key, user)
  File "/workspaces/dev/frappe-bench/apps/frappe/frappe/database/database.py", line 1027, in get_default
    d = self.get_defaults(key, parent)
  File "/workspaces/dev/frappe-bench/apps/frappe/frappe/database/database.py", line 1043, in get_defaults
    defaults = frappe.defaults.get_defaults_for(parent)
  File "/workspaces/dev/frappe-bench/apps/frappe/frappe/defaults.py", line 238, in get_defaults_for
    frappe.qb.from_(table)
  File "/workspaces/dev/frappe-bench/apps/frappe/frappe/query_builder/utils.py", line 87, in execute_query
    result = frappe.db.sql(query, params, *args, **kwargs)  # nosemgrep
  File "/workspaces/dev/frappe-bench/apps/frappe/frappe/database/database.py", line 220, in sql
    self.connect()
  File "/workspaces/dev/frappe-bench/apps/frappe/frappe/database/database.py", line 125, in connect
    self._conn: Union["MariadbConnection", "PostgresConnection"] = self.get_connection()
  File "/workspaces/dev/frappe-bench/apps/frappe/frappe/database/mariadb/database.py", line 99, in get_connection
    conn = self._get_connection()
  File "/workspaces/dev/frappe-bench/apps/frappe/frappe/database/mariadb/database.py", line 105, in _get_connection
    return self.create_connection()
  File "/workspaces/dev/frappe-bench/apps/frappe/frappe/database/mariadb/database.py", line 108, in create_connection
    return pymysql.connect(**self.get_connection_settings())
  File "/workspaces/dev/frappe-bench/env/lib/python3.10/site-packages/pymysql/connections.py", line 352, in __init__
    self.connect()
  File "/workspaces/dev/frappe-bench/env/lib/python3.10/site-packages/pymysql/connections.py", line 668, in connect
    raise exc
pymysql.err.OperationalError: (2003, "Can't connect to MySQL server on '127.0.0.1' ([Errno 111] Connection refused)")

During handling of the above exception, another exception occurred:

Traceback (most recent call last):
  File "/workspaces/dev/frappe-bench/apps/frappe/frappe/utils/caching.py", line 55, in wrapper
    return frappe.local.request_cache[func][args_key]
KeyError: -6990307785132406738

During handling of the above exception, another exception occurred:

Traceback (most recent call last):
  File "/workspaces/dev/frappe-bench/env/lib/python3.10/site-packages/pymysql/connections.py", line 616, in connect
    sock = socket.create_connection(
  File "/home/codespace/.python/current/lib/python3.10/socket.py", line 845, in create_connection
    raise err
  File "/home/codespace/.python/current/lib/python3.10/socket.py", line 833, in create_connection
    sock.connect(sa)
ConnectionRefusedError: [Errno 111] Connection refused

During handling of the above exception, another exception occurred:

Traceback (most recent call last):
  File "/workspaces/dev/frappe-bench/apps/frappe/frappe/app.py", line 113, in application
    response = handle_exception(e)
  File "/workspaces/dev/frappe-bench/apps/frappe/frappe/app.py", line 367, in handle_exception
    response = get_response("message", http_status_code=http_status_code)
  File "/workspaces/dev/frappe-bench/apps/frappe/frappe/website/serve.py", line 26, in get_response
    response = ErrorPage(exception=e).render()
  File "/workspaces/dev/frappe-bench/apps/frappe/frappe/website/page_renderers/error_page.py", line 7, in __init__
    super().__init__(path=path, http_status_code=http_status_code)
  File "/workspaces/dev/frappe-bench/apps/frappe/frappe/website/page_renderers/template_page.py", line 45, in __init__
    self.set_template_path()
  File "/workspaces/dev/frappe-bench/apps/frappe/frappe/website/page_renderers/template_page.py", line 53, in set_template_path
    for app in frappe.get_installed_apps(frappe_last=True):
  File "/workspaces/dev/frappe-bench/apps/frappe/frappe/utils/caching.py", line 57, in wrapper
    return_val = func(*args, **kwargs)
  File "/workspaces/dev/frappe-bench/apps/frappe/frappe/__init__.py", line 1419, in get_installed_apps
    installed = json.loads(db.get_global("installed_apps") or "[]")
  File "/workspaces/dev/frappe-bench/apps/frappe/frappe/database/database.py", line 1023, in get_global
    return self.get_default(key, user)
  File "/workspaces/dev/frappe-bench/apps/frappe/frappe/database/database.py", line 1027, in get_default
    d = self.get_defaults(key, parent)
  File "/workspaces/dev/frappe-bench/apps/frappe/frappe/database/database.py", line 1043, in get_defaults
    defaults = frappe.defaults.get_defaults_for(parent)
  File "/workspaces/dev/frappe-bench/apps/frappe/frappe/defaults.py", line 238, in get_defaults_for
    frappe.qb.from_(table)
  File "/workspaces/dev/frappe-bench/apps/frappe/frappe/query_builder/utils.py", line 87, in execute_query
    result = frappe.db.sql(query, params, *args, **kwargs)  # nosemgrep
  File "/workspaces/dev/frappe-bench/apps/frappe/frappe/database/database.py", line 220, in sql
    self.connect()
  File "/workspaces/dev/frappe-bench/apps/frappe/frappe/database/database.py", line 125, in connect
    self._conn: Union["MariadbConnection", "PostgresConnection"] = self.get_connection()
  File "/workspaces/dev/frappe-bench/apps/frappe/frappe/database/mariadb/database.py", line 99, in get_connection
    conn = self._get_connection()
  File "/workspaces/dev/frappe-bench/apps/frappe/frappe/database/mariadb/database.py", line 105, in _get_connection
    return self.create_connection()
  File "/workspaces/dev/frappe-bench/apps/frappe/frappe/database/mariadb/database.py", line 108, in create_connection
    return pymysql.connect(**self.get_connection_settings())
  File "/workspaces/dev/frappe-bench/env/lib/python3.10/site-packages/pymysql/connections.py", line 352, in __init__
    self.connect()
  File "/workspaces/dev/frappe-bench/env/lib/python3.10/site-packages/pymysql/connections.py", line 668, in connect
    raise exc
pymysql.err.OperationalError: (2003, "Can't connect to MySQL server on '127.0.0.1' ([Errno 111] Connection refused)")

During handling of the above exception, another exception occurred:

Traceback (most recent call last):
  File "/workspaces/dev/frappe-bench/apps/frappe/frappe/utils/caching.py", line 55, in wrapper
    return frappe.local.request_cache[func][args_key]
KeyError: 5740354900026072187

During handling of the above exception, another exception occurred:

Traceback (most recent call last):
  File "/workspaces/dev/frappe-bench/apps/frappe/frappe/utils/caching.py", line 55, in wrapper
    return frappe.local.request_cache[func][args_key]
KeyError: 1255897768722113620

During handling of the above exception, another exception occurred:

Traceback (most recent call last):
  File "/workspaces/dev/frappe-bench/env/lib/python3.10/site-packages/pymysql/connections.py", line 616, in connect
    sock = socket.create_connection(
  File "/home/codespace/.python/current/lib/python3.10/socket.py", line 845, in create_connection
    raise err
  File "/home/codespace/.python/current/lib/python3.10/socket.py", line 833, in create_connection
    sock.connect(sa)
ConnectionRefusedError: [Errno 111] Connection refused

During handling of the above exception, another exception occurred:

Traceback (most recent call last):
  File "/workspaces/dev/frappe-bench/apps/frappe/frappe/app.py", line 127, in application
    run_after_request_hooks(request, response)
  File "/workspaces/dev/frappe-bench/apps/frappe/frappe/app.py", line 143, in run_after_request_hooks
    for after_request_task in frappe.get_hooks("after_request"):
  File "/workspaces/dev/frappe-bench/apps/frappe/frappe/__init__.py", line 1498, in get_hooks
    hooks = _dict(cache().get_value("app_hooks", _load_app_hooks))
  File "/workspaces/dev/frappe-bench/apps/frappe/frappe/utils/redis_wrapper.py", line 81, in get_value
    val = generator()
  File "/workspaces/dev/frappe-bench/apps/frappe/frappe/utils/caching.py", line 57, in wrapper
    return_val = func(*args, **kwargs)
  File "/workspaces/dev/frappe-bench/apps/frappe/frappe/__init__.py", line 1463, in _load_app_hooks
    apps = [app_name] if app_name else get_installed_apps(_ensure_on_bench=True)
  File "/workspaces/dev/frappe-bench/apps/frappe/frappe/utils/caching.py", line 57, in wrapper
    return_val = func(*args, **kwargs)
  File "/workspaces/dev/frappe-bench/apps/frappe/frappe/__init__.py", line 1419, in get_installed_apps
    installed = json.loads(db.get_global("installed_apps") or "[]")
  File "/workspaces/dev/frappe-bench/apps/frappe/frappe/database/database.py", line 1023, in get_global
    return self.get_default(key, user)
  File "/workspaces/dev/frappe-bench/apps/frappe/frappe/database/database.py", line 1027, in get_default
    d = self.get_defaults(key, parent)
  File "/workspaces/dev/frappe-bench/apps/frappe/frappe/database/database.py", line 1043, in get_defaults
    defaults = frappe.defaults.get_defaults_for(parent)
  File "/workspaces/dev/frappe-bench/apps/frappe/frappe/defaults.py", line 238, in get_defaults_for
    frappe.qb.from_(table)
  File "/workspaces/dev/frappe-bench/apps/frappe/frappe/query_builder/utils.py", line 87, in execute_query
    result = frappe.db.sql(query, params, *args, **kwargs)  # nosemgrep
  File "/workspaces/dev/frappe-bench/apps/frappe/frappe/database/database.py", line 220, in sql
    self.connect()
  File "/workspaces/dev/frappe-bench/apps/frappe/frappe/database/database.py", line 125, in connect
    self._conn: Union["MariadbConnection", "PostgresConnection"] = self.get_connection()
  File "/workspaces/dev/frappe-bench/apps/frappe/frappe/database/mariadb/database.py", line 99, in get_connection
    conn = self._get_connection()
  File "/workspaces/dev/frappe-bench/apps/frappe/frappe/database/mariadb/database.py", line 105, in _get_connection
    return self.create_connection()
  File "/workspaces/dev/frappe-bench/apps/frappe/frappe/database/mariadb/database.py", line 108, in create_connection
    return pymysql.connect(**self.get_connection_settings())
  File "/workspaces/dev/frappe-bench/env/lib/python3.10/site-packages/pymysql/connections.py", line 352, in __init__
    self.connect()
  File "/workspaces/dev/frappe-bench/env/lib/python3.10/site-packages/pymysql/connections.py", line 668, in connect
    raise exc
pymysql.err.OperationalError: (2003, "Can't connect to MySQL server on '127.0.0.1' ([Errno 111] Connection refused)")
2024-02-19 09:03:51,647 ERROR frappe New Exception collected with id: 2024-02-19 09:03:51.635030-127.0.0.1-d08
Site: erp.com
Form Dict: {}
2024-02-19 09:03:51,653 ERROR frappe Failed to run after request hook
Site: erp.com
Form Dict: {}
Traceback (most recent call last):
  File "/workspaces/dev/frappe-bench/env/lib/python3.10/site-packages/pymysql/connections.py", line 616, in connect
    sock = socket.create_connection(
  File "/home/codespace/.python/current/lib/python3.10/socket.py", line 845, in create_connection
    raise err
  File "/home/codespace/.python/current/lib/python3.10/socket.py", line 833, in create_connection
    sock.connect(sa)
ConnectionRefusedError: [Errno 111] Connection refused

During handling of the above exception, another exception occurred:

Traceback (most recent call last):
  File "/workspaces/dev/frappe-bench/apps/frappe/frappe/app.py", line 84, in application
    init_request(request)
  File "/workspaces/dev/frappe-bench/apps/frappe/frappe/app.py", line 175, in init_request
    frappe.local.http_request = frappe.auth.HTTPRequest()
  File "/workspaces/dev/frappe-bench/apps/frappe/frappe/auth.py", line 37, in __init__
    self.set_session()
  File "/workspaces/dev/frappe-bench/apps/frappe/frappe/auth.py", line 71, in set_session
    frappe.local.login_manager = LoginManager()
  File "/workspaces/dev/frappe-bench/apps/frappe/frappe/auth.py", line 117, in __init__
    self.make_session(resume=True)
  File "/workspaces/dev/frappe-bench/apps/frappe/frappe/auth.py", line 203, in make_session
    frappe.local.session_obj = Session(
  File "/workspaces/dev/frappe-bench/apps/frappe/frappe/sessions.py", line 222, in __init__
    self.resume()
  File "/workspaces/dev/frappe-bench/apps/frappe/frappe/sessions.py", line 298, in resume
    validate_ip_address(self.user)
  File "/workspaces/dev/frappe-bench/apps/frappe/frappe/auth.py", line 418, in validate_ip_address
    frappe.get_cached_value("User", user, user_fields, as_dict=True)
  File "/workspaces/dev/frappe-bench/apps/frappe/frappe/__init__.py", line 1152, in get_cached_value
    doc = get_cached_doc(doctype, name)
  File "/workspaces/dev/frappe-bench/apps/frappe/frappe/__init__.py", line 1095, in get_cached_doc
    doc = get_doc(*args, **kwargs)
  File "/workspaces/dev/frappe-bench/apps/frappe/frappe/__init__.py", line 1186, in get_doc
    doc = frappe.model.document.get_doc(*args, **kwargs)
  File "/workspaces/dev/frappe-bench/apps/frappe/frappe/model/document.py", line 73, in get_doc
    controller = get_controller(doctype)
  File "/workspaces/dev/frappe-bench/apps/frappe/frappe/model/base_document.py", line 89, in get_controller
    return _get_controller()
  File "/workspaces/dev/frappe-bench/apps/frappe/frappe/model/base_document.py", line 59, in _get_controller
    module_name, custom = frappe.db.get_value(
  File "/workspaces/dev/frappe-bench/apps/frappe/frappe/database/database.py", line 556, in get_value
    result = self.get_values(
  File "/workspaces/dev/frappe-bench/apps/frappe/frappe/database/database.py", line 653, in get_values
    out = self._get_values_from_table(
  File "/workspaces/dev/frappe-bench/apps/frappe/frappe/database/database.py", line 883, in _get_values_from_table
    return query.run(as_dict=as_dict, debug=debug, update=update, run=run, pluck=pluck)
  File "/workspaces/dev/frappe-bench/apps/frappe/frappe/query_builder/utils.py", line 87, in execute_query
    result = frappe.db.sql(query, params, *args, **kwargs)  # nosemgrep
  File "/workspaces/dev/frappe-bench/apps/frappe/frappe/database/database.py", line 220, in sql
    self.connect()
  File "/workspaces/dev/frappe-bench/apps/frappe/frappe/database/database.py", line 125, in connect
    self._conn: Union["MariadbConnection", "PostgresConnection"] = self.get_connection()
  File "/workspaces/dev/frappe-bench/apps/frappe/frappe/database/mariadb/database.py", line 99, in get_connection
    conn = self._get_connection()
  File "/workspaces/dev/frappe-bench/apps/frappe/frappe/database/mariadb/database.py", line 105, in _get_connection
    return self.create_connection()
  File "/workspaces/dev/frappe-bench/apps/frappe/frappe/database/mariadb/database.py", line 108, in create_connection
    return pymysql.connect(**self.get_connection_settings())
  File "/workspaces/dev/frappe-bench/env/lib/python3.10/site-packages/pymysql/connections.py", line 352, in __init__
    self.connect()
  File "/workspaces/dev/frappe-bench/env/lib/python3.10/site-packages/pymysql/connections.py", line 668, in connect
    raise exc
pymysql.err.OperationalError: (2003, "Can't connect to MySQL server on '127.0.0.1' ([Errno 111] Connection refused)")

During handling of the above exception, another exception occurred:

Traceback (most recent call last):
  File "/workspaces/dev/frappe-bench/apps/frappe/frappe/utils/caching.py", line 55, in wrapper
    return frappe.local.request_cache[func][args_key]
KeyError: 5740354900026072187

During handling of the above exception, another exception occurred:

Traceback (most recent call last):
  File "/workspaces/dev/frappe-bench/apps/frappe/frappe/utils/caching.py", line 55, in wrapper
    return frappe.local.request_cache[func][args_key]
KeyError: 1255897768722113620

During handling of the above exception, another exception occurred:

Traceback (most recent call last):
  File "/workspaces/dev/frappe-bench/env/lib/python3.10/site-packages/pymysql/connections.py", line 616, in connect
    sock = socket.create_connection(
  File "/home/codespace/.python/current/lib/python3.10/socket.py", line 845, in create_connection
    raise err
  File "/home/codespace/.python/current/lib/python3.10/socket.py", line 833, in create_connection
    sock.connect(sa)
ConnectionRefusedError: [Errno 111] Connection refused

During handling of the above exception, another exception occurred:

Traceback (most recent call last):
  File "/workspaces/dev/frappe-bench/apps/frappe/frappe/website/serve.py", line 17, in get_response
    endpoint, renderer_instance = path_resolver.resolve()
  File "/workspaces/dev/frappe-bench/apps/frappe/frappe/website/path_resolver.py", line 36, in resolve
    resolve_redirect(self.path, request.query_string)
  File "/workspaces/dev/frappe-bench/apps/frappe/frappe/website/path_resolver.py", line 107, in resolve_redirect
    redirects = frappe.get_hooks("website_redirects")
  File "/workspaces/dev/frappe-bench/apps/frappe/frappe/__init__.py", line 1498, in get_hooks
    hooks = _dict(cache().get_value("app_hooks", _load_app_hooks))
  File "/workspaces/dev/frappe-bench/apps/frappe/frappe/utils/redis_wrapper.py", line 81, in get_value
    val = generator()
  File "/workspaces/dev/frappe-bench/apps/frappe/frappe/utils/caching.py", line 57, in wrapper
    return_val = func(*args, **kwargs)
  File "/workspaces/dev/frappe-bench/apps/frappe/frappe/__init__.py", line 1463, in _load_app_hooks
    apps = [app_name] if app_name else get_installed_apps(_ensure_on_bench=True)
  File "/workspaces/dev/frappe-bench/apps/frappe/frappe/utils/caching.py", line 57, in wrapper
    return_val = func(*args, **kwargs)
  File "/workspaces/dev/frappe-bench/apps/frappe/frappe/__init__.py", line 1419, in get_installed_apps
    installed = json.loads(db.get_global("installed_apps") or "[]")
  File "/workspaces/dev/frappe-bench/apps/frappe/frappe/database/database.py", line 1023, in get_global
    return self.get_default(key, user)
  File "/workspaces/dev/frappe-bench/apps/frappe/frappe/database/database.py", line 1027, in get_default
    d = self.get_defaults(key, parent)
  File "/workspaces/dev/frappe-bench/apps/frappe/frappe/database/database.py", line 1043, in get_defaults
    defaults = frappe.defaults.get_defaults_for(parent)
  File "/workspaces/dev/frappe-bench/apps/frappe/frappe/defaults.py", line 238, in get_defaults_for
    frappe.qb.from_(table)
  File "/workspaces/dev/frappe-bench/apps/frappe/frappe/query_builder/utils.py", line 87, in execute_query
    result = frappe.db.sql(query, params, *args, **kwargs)  # nosemgrep
  File "/workspaces/dev/frappe-bench/apps/frappe/frappe/database/database.py", line 220, in sql
    self.connect()
  File "/workspaces/dev/frappe-bench/apps/frappe/frappe/database/database.py", line 125, in connect
    self._conn: Union["MariadbConnection", "PostgresConnection"] = self.get_connection()
  File "/workspaces/dev/frappe-bench/apps/frappe/frappe/database/mariadb/database.py", line 99, in get_connection
    conn = self._get_connection()
  File "/workspaces/dev/frappe-bench/apps/frappe/frappe/database/mariadb/database.py", line 105, in _get_connection
    return self.create_connection()
  File "/workspaces/dev/frappe-bench/apps/frappe/frappe/database/mariadb/database.py", line 108, in create_connection
    return pymysql.connect(**self.get_connection_settings())
  File "/workspaces/dev/frappe-bench/env/lib/python3.10/site-packages/pymysql/connections.py", line 352, in __init__
    self.connect()
  File "/workspaces/dev/frappe-bench/env/lib/python3.10/site-packages/pymysql/connections.py", line 668, in connect
    raise exc
pymysql.err.OperationalError: (2003, "Can't connect to MySQL server on '127.0.0.1' ([Errno 111] Connection refused)")

During handling of the above exception, another exception occurred:

Traceback (most recent call last):
  File "/workspaces/dev/frappe-bench/apps/frappe/frappe/utils/caching.py", line 55, in wrapper
    return frappe.local.request_cache[func][args_key]
KeyError: -6990307785132406738

During handling of the above exception, another exception occurred:

Traceback (most recent call last):
  File "/workspaces/dev/frappe-bench/env/lib/python3.10/site-packages/pymysql/connections.py", line 616, in connect
    sock = socket.create_connection(
  File "/home/codespace/.python/current/lib/python3.10/socket.py", line 845, in create_connection
    raise err
  File "/home/codespace/.python/current/lib/python3.10/socket.py", line 833, in create_connection
    sock.connect(sa)
ConnectionRefusedError: [Errno 111] Connection refused

During handling of the above exception, another exception occurred:

Traceback (most recent call last):
  File "/workspaces/dev/frappe-bench/apps/frappe/frappe/app.py", line 113, in application
    response = handle_exception(e)
  File "/workspaces/dev/frappe-bench/apps/frappe/frappe/app.py", line 367, in handle_exception
    response = get_response("message", http_status_code=http_status_code)
  File "/workspaces/dev/frappe-bench/apps/frappe/frappe/website/serve.py", line 26, in get_response
    response = ErrorPage(exception=e).render()
  File "/workspaces/dev/frappe-bench/apps/frappe/frappe/website/page_renderers/error_page.py", line 7, in __init__
    super().__init__(path=path, http_status_code=http_status_code)
  File "/workspaces/dev/frappe-bench/apps/frappe/frappe/website/page_renderers/template_page.py", line 45, in __init__
    self.set_template_path()
  File "/workspaces/dev/frappe-bench/apps/frappe/frappe/website/page_renderers/template_page.py", line 53, in set_template_path
    for app in frappe.get_installed_apps(frappe_last=True):
  File "/workspaces/dev/frappe-bench/apps/frappe/frappe/utils/caching.py", line 57, in wrapper
    return_val = func(*args, **kwargs)
  File "/workspaces/dev/frappe-bench/apps/frappe/frappe/__init__.py", line 1419, in get_installed_apps
    installed = json.loads(db.get_global("installed_apps") or "[]")
  File "/workspaces/dev/frappe-bench/apps/frappe/frappe/database/database.py", line 1023, in get_global
    return self.get_default(key, user)
  File "/workspaces/dev/frappe-bench/apps/frappe/frappe/database/database.py", line 1027, in get_default
    d = self.get_defaults(key, parent)
  File "/workspaces/dev/frappe-bench/apps/frappe/frappe/database/database.py", line 1043, in get_defaults
    defaults = frappe.defaults.get_defaults_for(parent)
  File "/workspaces/dev/frappe-bench/apps/frappe/frappe/defaults.py", line 238, in get_defaults_for
    frappe.qb.from_(table)
  File "/workspaces/dev/frappe-bench/apps/frappe/frappe/query_builder/utils.py", line 87, in execute_query
    result = frappe.db.sql(query, params, *args, **kwargs)  # nosemgrep
  File "/workspaces/dev/frappe-bench/apps/frappe/frappe/database/database.py", line 220, in sql
    self.connect()
  File "/workspaces/dev/frappe-bench/apps/frappe/frappe/database/database.py", line 125, in connect
    self._conn: Union["MariadbConnection", "PostgresConnection"] = self.get_connection()
  File "/workspaces/dev/frappe-bench/apps/frappe/frappe/database/mariadb/database.py", line 99, in get_connection
    conn = self._get_connection()
  File "/workspaces/dev/frappe-bench/apps/frappe/frappe/database/mariadb/database.py", line 105, in _get_connection
    return self.create_connection()
  File "/workspaces/dev/frappe-bench/apps/frappe/frappe/database/mariadb/database.py", line 108, in create_connection
    return pymysql.connect(**self.get_connection_settings())
  File "/workspaces/dev/frappe-bench/env/lib/python3.10/site-packages/pymysql/connections.py", line 352, in __init__
    self.connect()
  File "/workspaces/dev/frappe-bench/env/lib/python3.10/site-packages/pymysql/connections.py", line 668, in connect
    raise exc
pymysql.err.OperationalError: (2003, "Can't connect to MySQL server on '127.0.0.1' ([Errno 111] Connection refused)")

During handling of the above exception, another exception occurred:

Traceback (most recent call last):
  File "/workspaces/dev/frappe-bench/apps/frappe/frappe/utils/caching.py", line 55, in wrapper
    return frappe.local.request_cache[func][args_key]
KeyError: 5740354900026072187

During handling of the above exception, another exception occurred:

Traceback (most recent call last):
  File "/workspaces/dev/frappe-bench/apps/frappe/frappe/utils/caching.py", line 55, in wrapper
    return frappe.local.request_cache[func][args_key]
KeyError: 1255897768722113620

During handling of the above exception, another exception occurred:

Traceback (most recent call last):
  File "/workspaces/dev/frappe-bench/env/lib/python3.10/site-packages/pymysql/connections.py", line 616, in connect
    sock = socket.create_connection(
  File "/home/codespace/.python/current/lib/python3.10/socket.py", line 845, in create_connection
    raise err
  File "/home/codespace/.python/current/lib/python3.10/socket.py", line 833, in create_connection
    sock.connect(sa)
ConnectionRefusedError: [Errno 111] Connection refused

During handling of the above exception, another exception occurred:

Traceback (most recent call last):
  File "/workspaces/dev/frappe-bench/apps/frappe/frappe/app.py", line 127, in application
    run_after_request_hooks(request, response)
  File "/workspaces/dev/frappe-bench/apps/frappe/frappe/app.py", line 143, in run_after_request_hooks
    for after_request_task in frappe.get_hooks("after_request"):
  File "/workspaces/dev/frappe-bench/apps/frappe/frappe/__init__.py", line 1498, in get_hooks
    hooks = _dict(cache().get_value("app_hooks", _load_app_hooks))
  File "/workspaces/dev/frappe-bench/apps/frappe/frappe/utils/redis_wrapper.py", line 81, in get_value
    val = generator()
  File "/workspaces/dev/frappe-bench/apps/frappe/frappe/utils/caching.py", line 57, in wrapper
    return_val = func(*args, **kwargs)
  File "/workspaces/dev/frappe-bench/apps/frappe/frappe/__init__.py", line 1463, in _load_app_hooks
    apps = [app_name] if app_name else get_installed_apps(_ensure_on_bench=True)
  File "/workspaces/dev/frappe-bench/apps/frappe/frappe/utils/caching.py", line 57, in wrapper
    return_val = func(*args, **kwargs)
  File "/workspaces/dev/frappe-bench/apps/frappe/frappe/__init__.py", line 1419, in get_installed_apps
    installed = json.loads(db.get_global("installed_apps") or "[]")
  File "/workspaces/dev/frappe-bench/apps/frappe/frappe/database/database.py", line 1023, in get_global
    return self.get_default(key, user)
  File "/workspaces/dev/frappe-bench/apps/frappe/frappe/database/database.py", line 1027, in get_default
    d = self.get_defaults(key, parent)
  File "/workspaces/dev/frappe-bench/apps/frappe/frappe/database/database.py", line 1043, in get_defaults
    defaults = frappe.defaults.get_defaults_for(parent)
  File "/workspaces/dev/frappe-bench/apps/frappe/frappe/defaults.py", line 238, in get_defaults_for
    frappe.qb.from_(table)
  File "/workspaces/dev/frappe-bench/apps/frappe/frappe/query_builder/utils.py", line 87, in execute_query
    result = frappe.db.sql(query, params, *args, **kwargs)  # nosemgrep
  File "/workspaces/dev/frappe-bench/apps/frappe/frappe/database/database.py", line 220, in sql
    self.connect()
  File "/workspaces/dev/frappe-bench/apps/frappe/frappe/database/database.py", line 125, in connect
    self._conn: Union["MariadbConnection", "PostgresConnection"] = self.get_connection()
  File "/workspaces/dev/frappe-bench/apps/frappe/frappe/database/mariadb/database.py", line 99, in get_connection
    conn = self._get_connection()
  File "/workspaces/dev/frappe-bench/apps/frappe/frappe/database/mariadb/database.py", line 105, in _get_connection
    return self.create_connection()
  File "/workspaces/dev/frappe-bench/apps/frappe/frappe/database/mariadb/database.py", line 108, in create_connection
    return pymysql.connect(**self.get_connection_settings())
  File "/workspaces/dev/frappe-bench/env/lib/python3.10/site-packages/pymysql/connections.py", line 352, in __init__
    self.connect()
  File "/workspaces/dev/frappe-bench/env/lib/python3.10/site-packages/pymysql/connections.py", line 668, in connect
    raise exc
pymysql.err.OperationalError: (2003, "Can't connect to MySQL server on '127.0.0.1' ([Errno 111] Connection refused)")
2024-02-19 09:03:51,938 ERROR frappe New Exception collected with id: 2024-02-19 09:03:51.928754-127.0.0.1-324
Site: erp.com
Form Dict: {}
